<sdf version='1.7'>
  <model name='differential_drive_robot'>
    <link name='body_link'>
      <inertial>
        <pose>0.021861 0 -0.007247 0 -0 0</pose>
        <mass>526.212</mass>
        <inertia>
          <ixx>18.996</ixx>
          <ixy>0</ixy>
          <ixz>1.06423</ixz>
          <iyy>48.2095</iyy>
          <iyz>0</iyz>
          <izz>58.8265</izz>
        </inertia>
      </inertial>
      <collision name='body_link_collision'>
        <pose>0 0 0 0 -0 0</pose>
        <geometry>
          <box>
            <size>1 0.6 0.3</size>
          </box>
        </geometry>
        <surface>
          <contact>
            <ode/>
          </contact>
          <friction>
            <ode>
              <mu>0.2</mu>
              <mu2>0.2</mu2>
            </ode>
          </friction>
        </surface>
      </collision>
      <collision name='body_link_fixed_joint_lump__caster_link_collision_1'>
        <pose>0.3 0 -0.1 0 -0 0</pose>
        <geometry>
          <sphere>
            <radius>0.15</radius>
          </sphere>
        </geometry>
        <surface>
          <contact>
            <ode/>
          </contact>
          <friction>
            <ode>
              <mu>2e-06</mu>
              <mu2>2e-06</mu2>
            </ode>
          </friction>
        </surface>
      </collision>
      <collision name='body_link_fixed_joint_lump__laser_frame_collision_2'>
        <pose>0.1 0 0.175 0 -0 0</pose>
        <geometry>
          <cylinder>
            <length>0.04</length>
            <radius>0.05</radius>
          </cylinder>
        </geometry>
        <surface>
          <contact>
            <ode/>
          </contact>
          <friction>
            <ode/>
          </friction>
        </surface>
      </collision>
      <visual name='body_link_visual'>
        <pose>0 0 0 0 -0 0</pose>
        <geometry>
          <box>
            <size>1 0.6 0.3</size>
          </box>
        </geometry>
        <material>
          <script>
            <name>Gazebo/Black</name>
            <uri>file://media/materials/scripts/gazebo.material</uri>
          </script>
        </material>
      </visual>
      <visual name='body_link_fixed_joint_lump__caster_link_visual_1'>
        <pose>0.3 0 -0.1 0 -0 0</pose>
        <geometry>
          <sphere>
            <radius>0.15</radius>
          </sphere>
        </geometry>
        <material>
          <script>
            <name>Gazebo/Blue</name>
            <uri>file://media/materials/scripts/gazebo.material</uri>
          </script>
        </material>
      </visual>
      <visual name='body_link_fixed_joint_lump__laser_frame_visual_2'>
        <pose>0.1 0 0.175 0 -0 0</pose>
        <geometry>
          <cylinder>
            <length>0.04</length>
            <radius>0.05</radius>
          </cylinder>
        </geometry>
        <material>
          <script>
            <name>Gazebo/Red</name>
            <uri>file://media/materials/scripts/gazebo.material</uri>
          </script>
        </material>
      </visual>
      <sensor name='laser' type='ray'>
        <visualize>1</visualize>
        <update_rate>10</update_rate>
        <ray>
          <scan>
            <horizontal>
              <samples>360</samples>
              <min_angle>-3.14</min_angle>
              <max_angle>3.14</max_angle>
              <resolution>1</resolution>
            </horizontal>
          </scan>
          <range>
            <min>0.3</min>
            <max>12</max>
          </range>
        </ray>
        <plugin name='laser_controller' filename='libgazebo_ros_laser.so'>
          <ros>
            <argument>~/out:=/scan</argument>
          </ros>
          <output_type>sensor_msgs/LaserScan</output_type>
          <frame_name>laser_frame</frame_name>
        </plugin>
        <pose>0.1 0 0.175 0 -0 0</pose>
      </sensor>
    </link>
    <joint name='wheel1_joint' type='revolute'>
      <pose relative_to='body_link'>-0.3 -0.35 -0.1 0 -0 0</pose>
      <parent>body_link</parent>
      <child>wheel1_link</child>
      <axis>
        <xyz>0 1 0</xyz>
        <limit>
          <effort>1000</effort>
          <velocity>1000</velocity>
          <lower>-1e+16</lower>
          <upper>1e+16</upper>
        </limit>
        <dynamics>
          <damping>1</damping>
          <friction>1</friction>
          <spring_reference>0</spring_reference>
          <spring_stiffness>0</spring_stiffness>
        </dynamics>
      </axis>
    </joint>
    <link name='wheel1_link'>
      <pose relative_to='wheel1_joint'>0 0 0 0 -0 0</pose>
      <inertial>
        <pose>0 0 0 0 -0 0</pose>
        <mass>19.1559</mass>
        <inertia>
          <ixx>0.123715</ixx>
          <ixy>0</ixy>
          <ixz>0</ixz>
          <iyy>0.123715</iyy>
          <iyz>0</iyz>
          <izz>0.215503</izz>
        </inertia>
      </inertial>
      <collision name='wheel1_link_collision'>
        <pose>0 0 0 1.57079 -0 0</pose>
        <geometry>
          <cylinder>
            <length>0.1</length>
            <radius>0.15</radius>
          </cylinder>
        </geometry>
        <surface>
          <contact>
            <ode/>
          </contact>
          <friction>
            <ode>
              <mu>0.2</mu>
              <mu2>0.2</mu2>
            </ode>
          </friction>
        </surface>
      </collision>
      <visual name='wheel1_link_visual'>
        <pose>0 0 0 1.57079 -0 0</pose>
        <geometry>
          <cylinder>
            <length>0.1</length>
            <radius>0.15</radius>
          </cylinder>
        </geometry>
        <material>
          <script>
            <name>Gazebo/Yellow</name>
            <uri>file://media/materials/scripts/gazebo.material</uri>
          </script>
        </material>
      </visual>
    </link>
    <joint name='wheel2_joint' type='revolute'>
      <pose relative_to='body_link'>-0.3 0.35 -0.1 0 -0 0</pose>
      <parent>body_link</parent>
      <child>wheel2_link</child>
      <axis>
        <xyz>0 1 0</xyz>
        <limit>
          <effort>1000</effort>
          <velocity>1000</velocity>
          <lower>-1e+16</lower>
          <upper>1e+16</upper>
        </limit>
        <dynamics>
          <damping>1</damping>
          <friction>1</friction>
          <spring_reference>0</spring_reference>
          <spring_stiffness>0</spring_stiffness>
        </dynamics>
      </axis>
    </joint>
    <link name='wheel2_link'>
      <pose relative_to='wheel2_joint'>0 0 0 0 -0 0</pose>
      <inertial>
        <pose>0 0 0 0 -0 0</pose>
        <mass>19.1559</mass>
        <inertia>
          <ixx>0.123715</ixx>
          <ixy>0</ixy>
          <ixz>0</ixz>
          <iyy>0.123715</iyy>
          <iyz>0</iyz>
          <izz>0.215503</izz>
        </inertia>
      </inertial>
      <collision name='wheel2_link_collision'>
        <pose>0 0 0 1.57079 -0 0</pose>
        <geometry>
          <cylinder>
            <length>0.1</length>
            <radius>0.15</radius>
          </cylinder>
        </geometry>
        <surface>
          <contact>
            <ode/>
          </contact>
          <friction>
            <ode>
              <mu>0.2</mu>
              <mu2>0.2</mu2>
            </ode>
          </friction>
        </surface>
      </collision>
      <visual name='wheel2_link_visual'>
        <pose>0 0 0 1.57079 -0 0</pose>
        <geometry>
          <cylinder>
            <length>0.1</length>
            <radius>0.15</radius>
          </cylinder>
        </geometry>
        <material>
          <script>
            <name>Gazebo/Yellow</name>
            <uri>file://media/materials/scripts/gazebo.material</uri>
          </script>
        </material>
      </visual>
    </link>
    <static>0</static>
    <plugin name='constant_force_plugin' filename='/home/uav/hero/install/butler/share/butler/lib/libforce_plugin.so'/>
  </model>
</sdf>
